<?xml version="1.0"?>
<robot name="abb_irb2400_12_155" xmlns:xacro="http://ros.org/wiki/xacro">

    <!-- link list -->
  <link name="base_link">
    <visual>
      <origin xyz="0 0 0" rpy="0 0 0"/>
      <geometry>
        <mesh filename="package://abb_irb2400_support/meshes/irb2400_common/visual/base_link.stl"/>
      </geometry>
      <material name="orange">
        <color rgba="1 0.43 0 1"/>
      </material>
    </visual>
    <collision>
      <geometry>
        <mesh filename="package://abb_irb2400_support/meshes/irb2400_common/collision/base_link.stl"/>
      </geometry>
      <material name="yellow">
        <color rgba="0 1 1 1"/>
      </material>
    </collision>
  </link>
  <link name="link_1">
    <visual>
      <origin xyz="0 0 0" rpy="0 0 0"/>
      <geometry>
         <mesh filename="package://abb_irb2400_support/meshes/irb2400_common/visual/link_1.stl"/>
      </geometry>
      <material name="orange"/>
    </visual>
    <collision>
      <origin xyz="0 0 0" rpy="0 0 0"/>
      <geometry>
        <mesh filename="package://abb_irb2400_support/meshes/irb2400_common/collision/link_1.stl"/>
      </geometry>
      <material name="yellow"/>
    </collision>
  </link>
  <link name="link_2">
    <visual>
      <origin xyz="0 0 0" rpy="0 0 0"/>
      <geometry>
        <mesh filename="package://abb_irb2400_support/meshes/irb2400_common/visual/link_2.stl"/>
      </geometry>
      <material name="orange"/>
    </visual>
    <collision>
      <origin xyz="0 0 0" rpy="0 0 0"/>
      <geometry>
        <mesh filename="package://abb_irb2400_support/meshes/irb2400_common/collision/link_2.stl"/>
      </geometry>
      <material name="yellow"/>
    </collision>
  </link>
  <link name="link_3">
    <visual>
      <origin xyz="0 0 0" rpy="0 0 0"/>
      <geometry>
        <mesh filename="package://abb_irb2400_support/meshes/irb2400_common/visual/link_3.stl"/>
      </geometry>
      <material name="orange"/>
    </visual>
    <collision>
      <origin xyz="0 0 0" rpy="0 0 0"/>
      <geometry>
        <mesh filename="package://abb_irb2400_support/meshes/irb2400_common/collision/link_3.stl"/>
      </geometry>
      <material name="yellow"/>
    </collision>
  </link>
  <link name="link_4">
    <visual>
      <origin xyz="0 0 0" rpy="0 0 0"/>
      <geometry>
        <mesh filename="package://abb_irb2400_support/meshes/irb2400_common/visual/link_4.stl"/>
      </geometry>
      <material name="orange"/>
    </visual>
    <collision>
      <origin xyz="0 0 0" rpy="0 0 0"/>
      <geometry>
        <mesh filename="package://abb_irb2400_support/meshes/irb2400_common/collision/link_4.stl"/>
      </geometry>
      <material name="yellow"/>
    </collision>
  </link>
  <link name="link_5">
    <visual>
      <origin xyz="0 0 0" rpy="0 0 0"/>
      <geometry>
        <mesh filename="package://abb_irb2400_support/meshes/irb2400_common/visual/link_5.stl"/>
      </geometry>
      <material name="orange"/>
    </visual>
    <collision>
      <origin xyz="0 0 0" rpy="0 0 0"/>
      <geometry>
        <mesh filename="package://abb_irb2400_support/meshes/irb2400_common/collision/link_5.stl"/>
      </geometry>
      <material name="yellow"/>
    </collision>
  </link>
  <link name="link_6">
    <visual>
      <origin xyz="0 0 0" rpy="0 0 0"/>
      <geometry>
        <mesh filename="package://abb_irb2400_support/meshes/irb2400_common/visual/link_6.stl"/>
      </geometry>
      <material name="black">
        <color rgba="0.1882353 0.1960784 0.2039216 1"/>
      </material>
    </visual>
    <collision>
      <origin xyz="0 0 0" rpy="0 0 0"/>
      <geometry>
        <mesh filename="package://abb_irb2400_support/meshes/irb2400_common/collision/link_6.stl"/>
      </geometry>
      <material name="yellow"/>
    </collision>
  </link>
  <link name="link_lever_a">
    <visual>
      <origin xyz="0 0 0" rpy="0 0 0"/>
      <geometry>
        <mesh filename="package://abb_irb2400_support/meshes/irb2400_common/visual/link_lever_a.stl"/>
      </geometry>
      <material name="black"/>
    </visual>
    <collision>
      <origin xyz="0 0 0" rpy="0 0 0"/>
      <geometry>
        <mesh filename="package://abb_irb2400_support/meshes/irb2400_common/collision/link_lever_a.stl"/>
      </geometry>
      <material name="yellow"/>
    </collision>
  </link>
  <link name="link_lever_b">
    <visual>
      <origin xyz="0 0 0" rpy="0 0 0"/>
      <geometry>
        <mesh filename="package://abb_irb2400_support/meshes/irb2400_common/visual/link_lever_b.stl"/>
      </geometry>
      <material name="black"/>
    </visual>
    <collision>
      <origin xyz="0 0 0" rpy="0 0 0"/>
      <geometry>
        <mesh filename="package://abb_irb2400_support/meshes/irb2400_common/collision/link_lever_b.stl"/>
      </geometry>
      <material name="yellow"/>
    </collision>
  </link>
  <link name="tool0"/>
  <!-- end of link list -->

  <!-- joint list -->
  <joint name="joint_1" type="revolute">
    <origin xyz="0 0 0" rpy="0 0 0"/>
    <parent link="base_link"/>
    <child link="link_1"/>
    <axis xyz="0 0 1"/>
    <limit lower="-3.1416" upper="3.1416" effort="0" velocity="2.618"/>
  </joint>
  <joint name="joint_2" type="revolute">
    <origin xyz="0.1 0 0.615" rpy="0 0 0"/>
    <parent link="link_1"/>
    <child link="link_2"/>
    <axis xyz="0 1 0"/>
    <limit lower="-1.7453" upper="1.9199" effort="0" velocity="2.618"/>
  </joint>
  <joint name="joint_3" type="revolute">
    <origin xyz="0 0 0.705" rpy="0 0 0"/>
    <parent link="link_2"/>
    <child link="link_3"/>
    <axis xyz="0 1 0"/>
    <limit lower="-1.0472" upper="1.1345" effort="0" velocity="2.618"/>
  </joint>
  <joint name="joint_4" type="revolute">
    <origin xyz="0 0 0.135" rpy="0 0 0"/>
    <parent link="link_3"/>
    <child link="link_4"/>
    <axis xyz="1 0 0"/>
    <limit lower="-3.49" upper="3.49" effort="0" velocity="6.2832"/>
  </joint>
  <joint name="joint_5" type="revolute">
    <origin xyz="0.755 0 0" rpy="0 0 0"/>
    <parent link="link_4"/>
    <child link="link_5"/>
    <axis xyz="0 1 0"/>
    <limit lower="-2.0944" upper="2.0944" effort="0" velocity="6.2832"/>
  </joint>
  <joint name="joint_6" type="revolute">
    <origin xyz="0 0 0" rpy="0 0 0"/>
    <parent link="link_5"/>
    <child link="link_6"/>
    <axis xyz="1 0 0"/>
    <limit lower="-6.9813" upper="6.9813" effort="0" velocity="7.854"/>
  </joint>
  <joint name="joint_lever_a" type="continuous">
    <origin xyz="0 0 0" rpy="0 0 0"/>
    <parent link="link_2"/>
    <child link="link_lever_a"/>
    <axis xyz="0 1 0"/>
    <mimic joint="joint_3" multiplier="1.0"/>
  </joint>
  <joint name="joint_lever_b" type="continuous">
    <origin xyz="-0.18 0 0" rpy="0 0 0"/>
    <parent link="link_3"/>
    <child link="link_lever_b"/>
    <axis xyz="0 1 0"/>
    <mimic joint="joint_3" multiplier="-1.0"/>
  </joint>
  <joint name="joint_6-tool0" type="fixed">
    <parent link="link_6"/>
    <child link="tool0"/>
    <origin xyz="0.085 0 0" rpy="0 1.57079632679 0"/>
  </joint>
  <!-- end of joint list -->

  <!-- ROS base_link to ABB World Coordinates transform -->
  <link name="base" />
  <joint name="base_link-base" type="fixed">
    <origin xyz="0 0 0" rpy="0 0 0"/>
    <parent link="base_link"/>
    <child link="base"/>
  </joint>
</robot>
